04.12.2022 15:43:52:4352|INFO|TG.handlers on_startup line:18|send main menu
04.12.2022 16:09:45:945|INFO|TG.handlers on_startup line:14|send main menu
04.12.2022 16:11:59:1159|INFO|TG.handlers on_startup line:14|send main menu
04.12.2022 16:13:14:1314|INFO|TG.handlers on_startup line:14|send main menu
04.12.2022 16:14:14:1414|INFO|TG.handlers on_startup line:14|send main menu
04.12.2022 16:15:33:1533|INFO|TG.handlers on_startup line:14|send main menu
04.12.2022 16:17:17:1717|INFO|TG.handlers on_startup line:14|send main menu
04.12.2022 16:18:10:1810|INFO|TG.handlers on_startup line:14|send main menu
04.12.2022 16:20:28:2028|INFO|TG.handlers on_startup line:14|send main menu
04.12.2022 16:20:50:2050|INFO|TG.handlers on_startup line:14|send main menu
04.12.2022 16:26:34:2634|INFO|TG.handlers on_startup line:15|send main menu
04.12.2022 16:28:02:282|INFO|TG.handlers on_startup line:15|send main menu
04.12.2022 16:29:22:2922|INFO|TG.handlers on_startup line:15|send main menu
04.12.2022 16:34:44:3444|INFO|TG.handlers on_startup line:15|send main menu
04.12.2022 16:36:13:3613|INFO|TG.handlers on_startup line:15|send main menu
04.12.2022 16:37:09:379|INFO|TG.handlers on_startup line:15|send main menu
04.12.2022 16:39:37:3937|INFO|TG.handlers on_startup line:15|send main menu
04.12.2022 16:42:29:4229|INFO|TG.handlers on_startup line:15|send main menu
04.12.2022 16:49:03:493|INFO|TG.handlers on_startup line:15|send main menu
04.12.2022 17:12:27:1227|INFO|TG.handlers on_startup line:15|send main menu
04.12.2022 17:12:36:1236|DEBUG|Api.api bug_catcher line:45|Ошибка /add_user/
Traceback (most recent call last):
  File "e:\Рабочий стол\house_manager_TG\Api\api.py", line 33, in bug_catcher
    data = await coro
  File "e:\Рабочий стол\house_manager_TG\Utility\database_connector.py", line 41, in add_user
    user_info['name'], user_info['id'], user_info['admin'], '', '', '', ''])
KeyError: 'name'

04.12.2022 17:12:36:1236|DEBUG|Api.api bug_catcher line:45|Ошибка /add_user/
Traceback (most recent call last):
  File "e:\Рабочий стол\house_manager_TG\Api\api.py", line 33, in bug_catcher
    data = await coro
  File "e:\Рабочий стол\house_manager_TG\Utility\database_connector.py", line 41, in add_user
    user_info['name'], user_info['id'], user_info['admin'], '', '', '', ''])
KeyError: 'name'

04.12.2022 17:12:36:1236|DEBUG|Api.api bug_catcher line:45|Ошибка /add_user/
Traceback (most recent call last):
  File "e:\Рабочий стол\house_manager_TG\Api\api.py", line 33, in bug_catcher
    data = await coro
  File "e:\Рабочий стол\house_manager_TG\Utility\database_connector.py", line 41, in add_user
    user_info['name'], user_info['id'], user_info['admin'], '', '', '', ''])
KeyError: 'name'

04.12.2022 17:12:36:1236|DEBUG|Api.api bug_catcher line:45|Ошибка /add_user/
Traceback (most recent call last):
  File "e:\Рабочий стол\house_manager_TG\Api\api.py", line 33, in bug_catcher
    data = await coro
  File "e:\Рабочий стол\house_manager_TG\Utility\database_connector.py", line 41, in add_user
    user_info['name'], user_info['id'], user_info['admin'], '', '', '', ''])
KeyError: 'name'

04.12.2022 17:12:36:1236|DEBUG|Api.api bug_catcher line:45|Ошибка /add_user/
Traceback (most recent call last):
  File "e:\Рабочий стол\house_manager_TG\Api\api.py", line 33, in bug_catcher
    data = await coro
  File "e:\Рабочий стол\house_manager_TG\Utility\database_connector.py", line 41, in add_user
    user_info['name'], user_info['id'], user_info['admin'], '', '', '', ''])
KeyError: 'name'

04.12.2022 17:13:26:1326|INFO|TG.handlers on_startup line:15|send main menu
04.12.2022 17:14:20:1420|INFO|TG.handlers on_startup line:15|send main menu
04.12.2022 17:14:31:1431|DEBUG|Api.api bug_catcher line:45|Ошибка /add_user/
Traceback (most recent call last):
  File "e:\Рабочий стол\house_manager_TG\Api\api.py", line 33, in bug_catcher
    data = await coro
  File "e:\Рабочий стол\house_manager_TG\Utility\database_connector.py", line 40, in add_user
    self.cursor.execute('INSERT INTO USER VALUES(???????)', [
sqlite3.OperationalError: near "?": syntax error

04.12.2022 17:14:31:1431|DEBUG|Api.api bug_catcher line:45|Ошибка /add_user/
Traceback (most recent call last):
  File "e:\Рабочий стол\house_manager_TG\Api\api.py", line 33, in bug_catcher
    data = await coro
  File "e:\Рабочий стол\house_manager_TG\Utility\database_connector.py", line 40, in add_user
    self.cursor.execute('INSERT INTO USER VALUES(???????)', [
sqlite3.OperationalError: near "?": syntax error

04.12.2022 17:14:31:1431|DEBUG|Api.api bug_catcher line:45|Ошибка /add_user/
Traceback (most recent call last):
  File "e:\Рабочий стол\house_manager_TG\Api\api.py", line 33, in bug_catcher
    data = await coro
  File "e:\Рабочий стол\house_manager_TG\Utility\database_connector.py", line 40, in add_user
    self.cursor.execute('INSERT INTO USER VALUES(???????)', [
sqlite3.OperationalError: near "?": syntax error

04.12.2022 17:14:31:1431|DEBUG|Api.api bug_catcher line:45|Ошибка /add_user/
Traceback (most recent call last):
  File "e:\Рабочий стол\house_manager_TG\Api\api.py", line 33, in bug_catcher
    data = await coro
  File "e:\Рабочий стол\house_manager_TG\Utility\database_connector.py", line 40, in add_user
    self.cursor.execute('INSERT INTO USER VALUES(???????)', [
sqlite3.OperationalError: near "?": syntax error

04.12.2022 17:14:31:1431|DEBUG|Api.api bug_catcher line:45|Ошибка /add_user/
Traceback (most recent call last):
  File "e:\Рабочий стол\house_manager_TG\Api\api.py", line 33, in bug_catcher
    data = await coro
  File "e:\Рабочий стол\house_manager_TG\Utility\database_connector.py", line 40, in add_user
    self.cursor.execute('INSERT INTO USER VALUES(???????)', [
sqlite3.OperationalError: near "?": syntax error

04.12.2022 17:14:57:1457|INFO|TG.handlers on_startup line:15|send main menu
04.12.2022 17:18:20:1820|INFO|TG.handlers on_startup line:17|send main menu
04.12.2022 17:33:13:3313|INFO|TG.handlers on_startup line:17|send main menu
04.12.2022 17:34:03:343|INFO|TG.handlers on_startup line:17|send main menu
04.12.2022 17:34:24:3424|INFO|TG.handlers on_startup line:17|send main menu
04.12.2022 17:34:51:3451|INFO|TG.handlers on_startup line:17|send main menu
04.12.2022 17:35:44:3544|INFO|TG.handlers on_startup line:17|send main menu
04.12.2022 17:36:18:3618|INFO|TG.handlers on_startup line:17|send main menu
04.12.2022 17:45:10:4510|INFO|TG.handlers on_startup line:17|send main menu
04.12.2022 18:04:18:418|INFO|TG.handlers on_startup line:17|send main menu
04.12.2022 18:05:08:58|INFO|TG.handlers on_startup line:17|send main menu
04.12.2022 18:11:45:1145|INFO|TG.handlers on_startup line:17|send main menu
04.12.2022 18:12:00:120|INFO|TG.handlers on_startup line:17|send main menu
04.12.2022 18:12:15:1215|INFO|TG.handlers on_startup line:17|send main menu
04.12.2022 18:16:26:1626|INFO|TG.handlers on_startup line:17|send main menu
04.12.2022 18:16:46:1646|INFO|TG.handlers on_startup line:17|send main menu
04.12.2022 18:17:23:1723|INFO|TG.handlers on_startup line:17|send main menu
04.12.2022 18:18:25:1825|INFO|TG.handlers on_startup line:17|send main menu
04.12.2022 18:24:53:2453|INFO|TG.handlers on_startup line:19|send main menu
04.12.2022 18:25:44:2544|INFO|TG.handlers on_startup line:20|send main menu
04.12.2022 18:26:43:2643|INFO|TG.handlers on_startup line:20|send main menu
04.12.2022 18:36:01:361|INFO|TG.handlers on_startup line:20|send main menu
04.12.2022 18:38:08:388|INFO|TG.handlers on_startup line:20|send main menu
04.12.2022 18:38:49:3849|INFO|TG.handlers on_startup line:20|send main menu
04.12.2022 18:59:18:5918|INFO|TG.handlers on_startup line:20|send main menu
04.12.2022 18:59:26:5926|DEBUG|Api.api bug_catcher line:51|Ошибка /add_user/
Traceback (most recent call last):
  File "e:\Рабочий стол\house_manager_TG\Api\api.py", line 39, in bug_catcher
    data = await coro
  File "e:\Рабочий стол\house_manager_TG\Utility\database_connector.py", line 57, in add_user
    self.cursor.execute('INSERT INTO USER VALUES(?,?,?)', [
sqlite3.OperationalError: table USER has 7 columns but 3 values were supplied

04.12.2022 18:59:26:5926|DEBUG|Api.api bug_catcher line:51|Ошибка /add_user/
Traceback (most recent call last):
  File "e:\Рабочий стол\house_manager_TG\Api\api.py", line 39, in bug_catcher
    data = await coro
  File "e:\Рабочий стол\house_manager_TG\Utility\database_connector.py", line 57, in add_user
    self.cursor.execute('INSERT INTO USER VALUES(?,?,?)', [
sqlite3.OperationalError: table USER has 7 columns but 3 values were supplied

04.12.2022 18:59:26:5926|DEBUG|Api.api bug_catcher line:51|Ошибка /add_user/
Traceback (most recent call last):
  File "e:\Рабочий стол\house_manager_TG\Api\api.py", line 39, in bug_catcher
    data = await coro
  File "e:\Рабочий стол\house_manager_TG\Utility\database_connector.py", line 57, in add_user
    self.cursor.execute('INSERT INTO USER VALUES(?,?,?)', [
sqlite3.OperationalError: table USER has 7 columns but 3 values were supplied

04.12.2022 18:59:26:5926|DEBUG|Api.api bug_catcher line:51|Ошибка /add_user/
Traceback (most recent call last):
  File "e:\Рабочий стол\house_manager_TG\Api\api.py", line 39, in bug_catcher
    data = await coro
  File "e:\Рабочий стол\house_manager_TG\Utility\database_connector.py", line 57, in add_user
    self.cursor.execute('INSERT INTO USER VALUES(?,?,?)', [
sqlite3.OperationalError: table USER has 7 columns but 3 values were supplied

04.12.2022 18:59:26:5926|DEBUG|Api.api bug_catcher line:51|Ошибка /add_user/
Traceback (most recent call last):
  File "e:\Рабочий стол\house_manager_TG\Api\api.py", line 39, in bug_catcher
    data = await coro
  File "e:\Рабочий стол\house_manager_TG\Utility\database_connector.py", line 57, in add_user
    self.cursor.execute('INSERT INTO USER VALUES(?,?,?)', [
sqlite3.OperationalError: table USER has 7 columns but 3 values were supplied

04.12.2022 19:00:03:03|INFO|TG.handlers on_startup line:20|send main menu
04.12.2022 19:28:52:2852|INFO|TG.handlers on_startup line:20|send main menu
04.12.2022 19:29:12:2912|INFO|TG.handlers on_startup line:20|send main menu
04.12.2022 19:29:32:2932|INFO|TG.handlers on_startup line:20|send main menu
04.12.2022 19:30:29:3029|INFO|TG.handlers on_startup line:20|send main menu
04.12.2022 19:31:48:3148|INFO|TG.handlers on_startup line:20|send main menu
04.12.2022 19:32:23:3223|INFO|TG.handlers on_startup line:20|send main menu
04.12.2022 19:48:13:4813|INFO|TG.handlers on_startup line:20|send main menu
04.12.2022 19:48:48:4848|INFO|TG.handlers on_startup line:20|send main menu
04.12.2022 19:49:36:4936|INFO|TG.handlers on_startup line:20|send main menu
04.12.2022 19:50:02:502|INFO|TG.handlers on_startup line:20|send main menu
04.12.2022 19:51:52:5152|INFO|TG.handlers on_startup line:20|send main menu
04.12.2022 19:52:07:527|INFO|TG.handlers on_startup line:20|send main menu
04.12.2022 19:52:40:5240|INFO|TG.handlers on_startup line:20|send main menu
04.12.2022 19:55:14:5514|INFO|TG.handlers on_startup line:20|send main menu
04.12.2022 20:39:49:3949|INFO|TG.handlers on_startup line:20|send main menu
04.12.2022 20:56:17:5617|INFO|TG.handlers on_startup line:20|send main menu
04.12.2022 20:56:34:5634|DEBUG|Api.api bug_catcher line:51|Ошибка /add_user/
Traceback (most recent call last):
  File "e:\Рабочий стол\house_manager_TG\Api\api.py", line 39, in bug_catcher
    data = await coro
  File "e:\Рабочий стол\house_manager_TG\Utility\database_connector.py", line 53, in add_user
    self.cursor.execute('INSERT INTO User VALUES(?,?,?,?,?,?,?)', [
sqlite3.ProgrammingError: Incorrect number of bindings supplied. The current statement uses 7, and there are 1 supplied.

04.12.2022 20:56:34:5634|DEBUG|Api.api bug_catcher line:51|Ошибка /add_user/
Traceback (most recent call last):
  File "e:\Рабочий стол\house_manager_TG\Api\api.py", line 39, in bug_catcher
    data = await coro
  File "e:\Рабочий стол\house_manager_TG\Utility\database_connector.py", line 53, in add_user
    self.cursor.execute('INSERT INTO User VALUES(?,?,?,?,?,?,?)', [
sqlite3.ProgrammingError: Incorrect number of bindings supplied. The current statement uses 7, and there are 1 supplied.

04.12.2022 20:56:34:5634|DEBUG|Api.api bug_catcher line:51|Ошибка /add_user/
Traceback (most recent call last):
  File "e:\Рабочий стол\house_manager_TG\Api\api.py", line 39, in bug_catcher
    data = await coro
  File "e:\Рабочий стол\house_manager_TG\Utility\database_connector.py", line 53, in add_user
    self.cursor.execute('INSERT INTO User VALUES(?,?,?,?,?,?,?)', [
sqlite3.ProgrammingError: Incorrect number of bindings supplied. The current statement uses 7, and there are 1 supplied.

04.12.2022 20:56:34:5634|DEBUG|Api.api bug_catcher line:51|Ошибка /add_user/
Traceback (most recent call last):
  File "e:\Рабочий стол\house_manager_TG\Api\api.py", line 39, in bug_catcher
    data = await coro
  File "e:\Рабочий стол\house_manager_TG\Utility\database_connector.py", line 53, in add_user
    self.cursor.execute('INSERT INTO User VALUES(?,?,?,?,?,?,?)', [
sqlite3.ProgrammingError: Incorrect number of bindings supplied. The current statement uses 7, and there are 1 supplied.

04.12.2022 20:56:34:5634|DEBUG|Api.api bug_catcher line:51|Ошибка /add_user/
Traceback (most recent call last):
  File "e:\Рабочий стол\house_manager_TG\Api\api.py", line 39, in bug_catcher
    data = await coro
  File "e:\Рабочий стол\house_manager_TG\Utility\database_connector.py", line 53, in add_user
    self.cursor.execute('INSERT INTO User VALUES(?,?,?,?,?,?,?)', [
sqlite3.ProgrammingError: Incorrect number of bindings supplied. The current statement uses 7, and there are 1 supplied.

04.12.2022 20:57:04:574|INFO|TG.handlers on_startup line:20|send main menu
04.12.2022 20:57:48:5748|INFO|TG.handlers on_startup line:20|send main menu
04.12.2022 20:58:50:5850|INFO|TG.handlers on_startup line:20|send main menu
04.12.2022 20:59:07:597|INFO|TG.handlers on_startup line:20|send main menu
04.12.2022 21:01:35:135|INFO|TG.handlers on_startup line:20|send main menu
04.12.2022 21:20:49:2049|INFO|TG.handlers on_startup line:20|send main menu
04.12.2022 21:21:26:2126|INFO|TG.handlers on_startup line:20|send main menu
04.12.2022 21:22:01:221|INFO|TG.handlers on_startup line:20|send main menu
04.12.2022 21:25:38:2538|INFO|TG.handlers on_startup line:20|send main menu
04.12.2022 21:26:51:2651|INFO|TG.handlers on_startup line:20|send main menu
04.12.2022 21:28:36:2836|INFO|TG.handlers on_startup line:20|send main menu
04.12.2022 21:28:57:2857|INFO|TG.handlers on_startup line:20|send main menu
04.12.2022 21:29:26:2926|INFO|TG.handlers on_startup line:20|send main menu
04.12.2022 21:30:14:3014|INFO|TG.handlers on_startup line:20|send main menu
04.12.2022 21:30:49:3049|INFO|TG.handlers on_startup line:20|send main menu
04.12.2022 21:31:13:3113|INFO|TG.handlers on_startup line:20|send main menu
04.12.2022 21:37:51:3751|INFO|TG.handlers on_startup line:20|send main menu
04.12.2022 21:38:23:3823|INFO|TG.handlers on_startup line:20|send main menu
04.12.2022 21:38:53:3853|INFO|TG.handlers on_startup line:19|send main menu
04.12.2022 21:39:15:3915|INFO|TG.handlers on_startup line:19|send main menu
04.12.2022 21:39:31:3931|INFO|TG.handlers on_startup line:19|send main menu
04.12.2022 21:39:59:3959|INFO|TG.handlers on_startup line:19|send main menu
04.12.2022 21:45:22:4522|INFO|TG.handlers on_startup line:19|send main menu
04.12.2022 21:45:57:4557|INFO|TG.handlers on_startup line:19|send main menu
04.12.2022 21:46:41:4641|INFO|TG.handlers on_startup line:19|send main menu
04.12.2022 21:46:44:4644|DEBUG|Api.api bug_catcher line:51|Ошибка /update_user/
Traceback (most recent call last):
  File "e:\Рабочий стол\house_manager_TG\Api\api.py", line 39, in bug_catcher
    data = await coro
  File "e:\Рабочий стол\house_manager_TG\Utility\database_connector.py", line 77, in update_user
    self.cursor.execute(_str)
sqlite3.OperationalError: near "table": syntax error

04.12.2022 21:46:44:4644|DEBUG|Api.api bug_catcher line:51|Ошибка /update_user/
Traceback (most recent call last):
  File "e:\Рабочий стол\house_manager_TG\Api\api.py", line 39, in bug_catcher
    data = await coro
  File "e:\Рабочий стол\house_manager_TG\Utility\database_connector.py", line 77, in update_user
    self.cursor.execute(_str)
sqlite3.OperationalError: near "table": syntax error

04.12.2022 21:46:44:4644|DEBUG|Api.api bug_catcher line:51|Ошибка /update_user/
Traceback (most recent call last):
  File "e:\Рабочий стол\house_manager_TG\Api\api.py", line 39, in bug_catcher
    data = await coro
  File "e:\Рабочий стол\house_manager_TG\Utility\database_connector.py", line 77, in update_user
    self.cursor.execute(_str)
sqlite3.OperationalError: near "table": syntax error

04.12.2022 21:46:44:4644|DEBUG|Api.api bug_catcher line:51|Ошибка /update_user/
Traceback (most recent call last):
  File "e:\Рабочий стол\house_manager_TG\Api\api.py", line 39, in bug_catcher
    data = await coro
  File "e:\Рабочий стол\house_manager_TG\Utility\database_connector.py", line 77, in update_user
    self.cursor.execute(_str)
sqlite3.OperationalError: near "table": syntax error

04.12.2022 21:46:44:4644|DEBUG|Api.api bug_catcher line:51|Ошибка /update_user/
Traceback (most recent call last):
  File "e:\Рабочий стол\house_manager_TG\Api\api.py", line 39, in bug_catcher
    data = await coro
  File "e:\Рабочий стол\house_manager_TG\Utility\database_connector.py", line 77, in update_user
    self.cursor.execute(_str)
sqlite3.OperationalError: near "table": syntax error

04.12.2022 21:46:47:4647|DEBUG|Api.api bug_catcher line:51|Ошибка /update_user/
Traceback (most recent call last):
  File "e:\Рабочий стол\house_manager_TG\Api\api.py", line 39, in bug_catcher
    data = await coro
  File "e:\Рабочий стол\house_manager_TG\Utility\database_connector.py", line 77, in update_user
    self.cursor.execute(_str)
sqlite3.OperationalError: near "table": syntax error

04.12.2022 21:46:47:4647|DEBUG|Api.api bug_catcher line:51|Ошибка /update_user/
Traceback (most recent call last):
  File "e:\Рабочий стол\house_manager_TG\Api\api.py", line 39, in bug_catcher
    data = await coro
  File "e:\Рабочий стол\house_manager_TG\Utility\database_connector.py", line 77, in update_user
    self.cursor.execute(_str)
sqlite3.OperationalError: near "table": syntax error

04.12.2022 21:46:47:4647|DEBUG|Api.api bug_catcher line:51|Ошибка /update_user/
Traceback (most recent call last):
  File "e:\Рабочий стол\house_manager_TG\Api\api.py", line 39, in bug_catcher
    data = await coro
  File "e:\Рабочий стол\house_manager_TG\Utility\database_connector.py", line 77, in update_user
    self.cursor.execute(_str)
sqlite3.OperationalError: near "table": syntax error

04.12.2022 21:46:47:4647|DEBUG|Api.api bug_catcher line:51|Ошибка /update_user/
Traceback (most recent call last):
  File "e:\Рабочий стол\house_manager_TG\Api\api.py", line 39, in bug_catcher
    data = await coro
  File "e:\Рабочий стол\house_manager_TG\Utility\database_connector.py", line 77, in update_user
    self.cursor.execute(_str)
sqlite3.OperationalError: near "table": syntax error

04.12.2022 21:46:47:4647|DEBUG|Api.api bug_catcher line:51|Ошибка /update_user/
Traceback (most recent call last):
  File "e:\Рабочий стол\house_manager_TG\Api\api.py", line 39, in bug_catcher
    data = await coro
  File "e:\Рабочий стол\house_manager_TG\Utility\database_connector.py", line 77, in update_user
    self.cursor.execute(_str)
sqlite3.OperationalError: near "table": syntax error

04.12.2022 21:46:47:4647|DEBUG|Api.api bug_catcher line:51|Ошибка /update_user/
Traceback (most recent call last):
  File "e:\Рабочий стол\house_manager_TG\Api\api.py", line 39, in bug_catcher
    data = await coro
  File "e:\Рабочий стол\house_manager_TG\Utility\database_connector.py", line 77, in update_user
    self.cursor.execute(_str)
sqlite3.OperationalError: near "table": syntax error

04.12.2022 21:46:47:4647|DEBUG|Api.api bug_catcher line:51|Ошибка /update_user/
Traceback (most recent call last):
  File "e:\Рабочий стол\house_manager_TG\Api\api.py", line 39, in bug_catcher
    data = await coro
  File "e:\Рабочий стол\house_manager_TG\Utility\database_connector.py", line 77, in update_user
    self.cursor.execute(_str)
sqlite3.OperationalError: near "table": syntax error

04.12.2022 21:46:47:4647|DEBUG|Api.api bug_catcher line:51|Ошибка /update_user/
Traceback (most recent call last):
  File "e:\Рабочий стол\house_manager_TG\Api\api.py", line 39, in bug_catcher
    data = await coro
  File "e:\Рабочий стол\house_manager_TG\Utility\database_connector.py", line 77, in update_user
    self.cursor.execute(_str)
sqlite3.OperationalError: near "table": syntax error

04.12.2022 21:46:47:4647|DEBUG|Api.api bug_catcher line:51|Ошибка /update_user/
Traceback (most recent call last):
  File "e:\Рабочий стол\house_manager_TG\Api\api.py", line 39, in bug_catcher
    data = await coro
  File "e:\Рабочий стол\house_manager_TG\Utility\database_connector.py", line 77, in update_user
    self.cursor.execute(_str)
sqlite3.OperationalError: near "table": syntax error

04.12.2022 21:46:47:4647|DEBUG|Api.api bug_catcher line:51|Ошибка /update_user/
Traceback (most recent call last):
  File "e:\Рабочий стол\house_manager_TG\Api\api.py", line 39, in bug_catcher
    data = await coro
  File "e:\Рабочий стол\house_manager_TG\Utility\database_connector.py", line 77, in update_user
    self.cursor.execute(_str)
sqlite3.OperationalError: near "table": syntax error

04.12.2022 21:47:49:4749|INFO|TG.handlers on_startup line:19|send main menu
04.12.2022 21:58:28:5828|INFO|TG.handlers on_startup line:19|send main menu
04.12.2022 23:16:17:1617|INFO|TG.handlers on_startup line:20|send main menu
04.12.2022 23:28:47:2847|INFO|TG.handlers on_startup line:20|send main menu
04.12.2022 23:29:06:296|DEBUG|Api.api bug_catcher line:51|Ошибка /get_columns_names/
Traceback (most recent call last):
  File "e:\Рабочий стол\house_manager_TG\Api\api.py", line 39, in bug_catcher
    data = await coro
TypeError: object list can't be used in 'await' expression

04.12.2022 23:29:06:296|DEBUG|Api.api bug_catcher line:51|Ошибка /get_columns_names/
Traceback (most recent call last):
  File "e:\Рабочий стол\house_manager_TG\Api\api.py", line 39, in bug_catcher
    data = await coro
TypeError: object list can't be used in 'await' expression

04.12.2022 23:29:06:296|DEBUG|Api.api bug_catcher line:51|Ошибка /get_columns_names/
Traceback (most recent call last):
  File "e:\Рабочий стол\house_manager_TG\Api\api.py", line 39, in bug_catcher
    data = await coro
TypeError: object list can't be used in 'await' expression

04.12.2022 23:29:06:296|DEBUG|Api.api bug_catcher line:51|Ошибка /get_columns_names/
Traceback (most recent call last):
  File "e:\Рабочий стол\house_manager_TG\Api\api.py", line 39, in bug_catcher
    data = await coro
TypeError: object list can't be used in 'await' expression

04.12.2022 23:29:06:296|DEBUG|Api.api bug_catcher line:51|Ошибка /get_columns_names/
Traceback (most recent call last):
  File "e:\Рабочий стол\house_manager_TG\Api\api.py", line 39, in bug_catcher
    data = await coro
TypeError: object list can't be used in 'await' expression

04.12.2022 23:30:25:3025|INFO|TG.handlers on_startup line:20|send main menu
04.12.2022 23:31:08:318|INFO|TG.handlers on_startup line:20|send main menu
04.12.2022 23:32:32:3232|INFO|TG.handlers on_startup line:20|send main menu
05.12.2022 00:05:30:530|INFO|TG.handlers on_startup line:20|send main menu
05.12.2022 00:48:28:4828|INFO|TG.handlers on_startup line:20|send main menu
05.12.2022 00:49:31:4931|INFO|TG.handlers on_startup line:20|send main menu
05.12.2022 00:52:23:5223|INFO|TG.handlers on_startup line:20|send main menu
05.12.2022 00:53:27:5327|INFO|TG.handlers on_startup line:20|send main menu
05.12.2022 00:54:42:5442|INFO|TG.handlers on_startup line:20|send main menu
05.12.2022 00:56:58:5658|INFO|TG.handlers on_startup line:20|send main menu
05.12.2022 00:58:05:585|INFO|TG.handlers on_startup line:20|send main menu
05.12.2022 00:59:12:5912|INFO|TG.handlers on_startup line:20|send main menu
05.12.2022 01:04:47:447|INFO|TG.handlers on_startup line:20|send main menu
05.12.2022 01:05:38:538|INFO|TG.handlers on_startup line:20|send main menu
05.12.2022 01:06:15:615|INFO|TG.handlers on_startup line:20|send main menu
05.12.2022 01:07:40:740|INFO|TG.handlers on_startup line:20|send main menu
05.12.2022 01:09:13:913|INFO|TG.handlers on_startup line:20|send main menu
05.12.2022 01:10:06:106|INFO|TG.handlers on_startup line:20|send main menu
05.12.2022 01:11:11:1111|INFO|TG.handlers on_startup line:20|send main menu
05.12.2022 01:12:19:1219|INFO|TG.handlers on_startup line:20|send main menu
05.12.2022 15:03:11:311|INFO|TG.handlers on_startup line:20|send main menu
05.12.2022 15:04:15:415|INFO|TG.handlers on_startup line:20|send main menu
05.12.2022 15:06:12:612|INFO|TG.handlers on_startup line:20|send main menu
05.12.2022 15:46:56:4656|INFO|TG.handlers on_startup line:20|send main menu
05.12.2022 15:47:33:4733|INFO|TG.handlers on_startup line:20|send main menu
05.12.2022 15:47:36:4736|DEBUG|Api.api bug_catcher line:68|Ошибка /get_report_with_current_date/
Traceback (most recent call last):
  File "e:\Рабочий стол\house_manager_TG\Api\api.py", line 56, in bug_catcher
    data = await coro
  File "e:\Рабочий стол\house_manager_TG\Utility\database_connector.py", line 105, in get_report_with_current_date
    ans = self.cursor.execute(f'SELECT * FROM {name_table} WHERE id={user_id} AND WHERE date={date}').fetchone()
sqlite3.OperationalError: near "WHERE": syntax error

05.12.2022 15:47:36:4736|DEBUG|Api.api bug_catcher line:68|Ошибка /get_report_with_current_date/
Traceback (most recent call last):
  File "e:\Рабочий стол\house_manager_TG\Api\api.py", line 56, in bug_catcher
    data = await coro
  File "e:\Рабочий стол\house_manager_TG\Utility\database_connector.py", line 105, in get_report_with_current_date
    ans = self.cursor.execute(f'SELECT * FROM {name_table} WHERE id={user_id} AND WHERE date={date}').fetchone()
sqlite3.OperationalError: near "WHERE": syntax error

05.12.2022 15:47:36:4736|DEBUG|Api.api bug_catcher line:68|Ошибка /get_report_with_current_date/
Traceback (most recent call last):
  File "e:\Рабочий стол\house_manager_TG\Api\api.py", line 56, in bug_catcher
    data = await coro
  File "e:\Рабочий стол\house_manager_TG\Utility\database_connector.py", line 105, in get_report_with_current_date
    ans = self.cursor.execute(f'SELECT * FROM {name_table} WHERE id={user_id} AND WHERE date={date}').fetchone()
sqlite3.OperationalError: near "WHERE": syntax error

05.12.2022 15:47:36:4736|DEBUG|Api.api bug_catcher line:68|Ошибка /get_report_with_current_date/
Traceback (most recent call last):
  File "e:\Рабочий стол\house_manager_TG\Api\api.py", line 56, in bug_catcher
    data = await coro
  File "e:\Рабочий стол\house_manager_TG\Utility\database_connector.py", line 105, in get_report_with_current_date
    ans = self.cursor.execute(f'SELECT * FROM {name_table} WHERE id={user_id} AND WHERE date={date}').fetchone()
sqlite3.OperationalError: near "WHERE": syntax error

05.12.2022 15:47:36:4736|DEBUG|Api.api bug_catcher line:68|Ошибка /get_report_with_current_date/
Traceback (most recent call last):
  File "e:\Рабочий стол\house_manager_TG\Api\api.py", line 56, in bug_catcher
    data = await coro
  File "e:\Рабочий стол\house_manager_TG\Utility\database_connector.py", line 105, in get_report_with_current_date
    ans = self.cursor.execute(f'SELECT * FROM {name_table} WHERE id={user_id} AND WHERE date={date}').fetchone()
sqlite3.OperationalError: near "WHERE": syntax error

05.12.2022 15:48:34:4834|INFO|TG.handlers on_startup line:20|send main menu
05.12.2022 15:49:02:492|INFO|TG.handlers on_startup line:20|send main menu
05.12.2022 15:49:05:495|DEBUG|Api.api bug_catcher line:68|Ошибка /get_report_with_current_date/
Traceback (most recent call last):
  File "e:\Рабочий стол\house_manager_TG\Api\api.py", line 56, in bug_catcher
    data = await coro
  File "e:\Рабочий стол\house_manager_TG\Utility\database_connector.py", line 105, in get_report_with_current_date
    ans = self.cursor.execute(f'SELECT * FROM {name_table} WHERE id={user_id} AND WHERE date={date}').fetchone()
sqlite3.OperationalError: near "WHERE": syntax error

05.12.2022 15:49:05:495|DEBUG|Api.api bug_catcher line:68|Ошибка /get_report_with_current_date/
Traceback (most recent call last):
  File "e:\Рабочий стол\house_manager_TG\Api\api.py", line 56, in bug_catcher
    data = await coro
  File "e:\Рабочий стол\house_manager_TG\Utility\database_connector.py", line 105, in get_report_with_current_date
    ans = self.cursor.execute(f'SELECT * FROM {name_table} WHERE id={user_id} AND WHERE date={date}').fetchone()
sqlite3.OperationalError: near "WHERE": syntax error

05.12.2022 15:49:05:495|DEBUG|Api.api bug_catcher line:68|Ошибка /get_report_with_current_date/
Traceback (most recent call last):
  File "e:\Рабочий стол\house_manager_TG\Api\api.py", line 56, in bug_catcher
    data = await coro
  File "e:\Рабочий стол\house_manager_TG\Utility\database_connector.py", line 105, in get_report_with_current_date
    ans = self.cursor.execute(f'SELECT * FROM {name_table} WHERE id={user_id} AND WHERE date={date}').fetchone()
sqlite3.OperationalError: near "WHERE": syntax error

05.12.2022 15:49:05:495|DEBUG|Api.api bug_catcher line:68|Ошибка /get_report_with_current_date/
Traceback (most recent call last):
  File "e:\Рабочий стол\house_manager_TG\Api\api.py", line 56, in bug_catcher
    data = await coro
  File "e:\Рабочий стол\house_manager_TG\Utility\database_connector.py", line 105, in get_report_with_current_date
    ans = self.cursor.execute(f'SELECT * FROM {name_table} WHERE id={user_id} AND WHERE date={date}').fetchone()
sqlite3.OperationalError: near "WHERE": syntax error

05.12.2022 15:49:05:495|DEBUG|Api.api bug_catcher line:68|Ошибка /get_report_with_current_date/
Traceback (most recent call last):
  File "e:\Рабочий стол\house_manager_TG\Api\api.py", line 56, in bug_catcher
    data = await coro
  File "e:\Рабочий стол\house_manager_TG\Utility\database_connector.py", line 105, in get_report_with_current_date
    ans = self.cursor.execute(f'SELECT * FROM {name_table} WHERE id={user_id} AND WHERE date={date}').fetchone()
sqlite3.OperationalError: near "WHERE": syntax error

05.12.2022 15:49:08:498|DEBUG|Api.api bug_catcher line:68|Ошибка /get_report_with_current_date/
Traceback (most recent call last):
  File "e:\Рабочий стол\house_manager_TG\Api\api.py", line 56, in bug_catcher
    data = await coro
  File "e:\Рабочий стол\house_manager_TG\Utility\database_connector.py", line 105, in get_report_with_current_date
    ans = self.cursor.execute(f'SELECT * FROM {name_table} WHERE id={user_id} AND WHERE date={date}').fetchone()
sqlite3.OperationalError: near "WHERE": syntax error

05.12.2022 15:49:08:498|DEBUG|Api.api bug_catcher line:68|Ошибка /get_report_with_current_date/
Traceback (most recent call last):
  File "e:\Рабочий стол\house_manager_TG\Api\api.py", line 56, in bug_catcher
    data = await coro
  File "e:\Рабочий стол\house_manager_TG\Utility\database_connector.py", line 105, in get_report_with_current_date
    ans = self.cursor.execute(f'SELECT * FROM {name_table} WHERE id={user_id} AND WHERE date={date}').fetchone()
sqlite3.OperationalError: near "WHERE": syntax error

05.12.2022 15:49:08:498|DEBUG|Api.api bug_catcher line:68|Ошибка /get_report_with_current_date/
Traceback (most recent call last):
  File "e:\Рабочий стол\house_manager_TG\Api\api.py", line 56, in bug_catcher
    data = await coro
  File "e:\Рабочий стол\house_manager_TG\Utility\database_connector.py", line 105, in get_report_with_current_date
    ans = self.cursor.execute(f'SELECT * FROM {name_table} WHERE id={user_id} AND WHERE date={date}').fetchone()
sqlite3.OperationalError: near "WHERE": syntax error

05.12.2022 15:49:08:498|DEBUG|Api.api bug_catcher line:68|Ошибка /get_report_with_current_date/
Traceback (most recent call last):
  File "e:\Рабочий стол\house_manager_TG\Api\api.py", line 56, in bug_catcher
    data = await coro
  File "e:\Рабочий стол\house_manager_TG\Utility\database_connector.py", line 105, in get_report_with_current_date
    ans = self.cursor.execute(f'SELECT * FROM {name_table} WHERE id={user_id} AND WHERE date={date}').fetchone()
sqlite3.OperationalError: near "WHERE": syntax error

05.12.2022 15:49:08:498|DEBUG|Api.api bug_catcher line:68|Ошибка /get_report_with_current_date/
Traceback (most recent call last):
  File "e:\Рабочий стол\house_manager_TG\Api\api.py", line 56, in bug_catcher
    data = await coro
  File "e:\Рабочий стол\house_manager_TG\Utility\database_connector.py", line 105, in get_report_with_current_date
    ans = self.cursor.execute(f'SELECT * FROM {name_table} WHERE id={user_id} AND WHERE date={date}').fetchone()
sqlite3.OperationalError: near "WHERE": syntax error

05.12.2022 16:13:56:1356|INFO|TG.handlers on_startup line:20|send main menu
05.12.2022 16:14:01:141|DEBUG|Api.api bug_catcher line:68|Ошибка /get_report_with_current_date/
Traceback (most recent call last):
  File "e:\Рабочий стол\house_manager_TG\Api\api.py", line 56, in bug_catcher
    data = await coro
  File "e:\Рабочий стол\house_manager_TG\Utility\database_connector.py", line 105, in get_report_with_current_date
    ans = self.cursor.execute(
sqlite3.OperationalError: no such column: id

05.12.2022 16:14:01:141|DEBUG|Api.api bug_catcher line:68|Ошибка /get_report_with_current_date/
Traceback (most recent call last):
  File "e:\Рабочий стол\house_manager_TG\Api\api.py", line 56, in bug_catcher
    data = await coro
  File "e:\Рабочий стол\house_manager_TG\Utility\database_connector.py", line 105, in get_report_with_current_date
    ans = self.cursor.execute(
sqlite3.OperationalError: no such column: id

05.12.2022 16:14:01:141|DEBUG|Api.api bug_catcher line:68|Ошибка /get_report_with_current_date/
Traceback (most recent call last):
  File "e:\Рабочий стол\house_manager_TG\Api\api.py", line 56, in bug_catcher
    data = await coro
  File "e:\Рабочий стол\house_manager_TG\Utility\database_connector.py", line 105, in get_report_with_current_date
    ans = self.cursor.execute(
sqlite3.OperationalError: no such column: id

05.12.2022 16:14:01:141|DEBUG|Api.api bug_catcher line:68|Ошибка /get_report_with_current_date/
Traceback (most recent call last):
  File "e:\Рабочий стол\house_manager_TG\Api\api.py", line 56, in bug_catcher
    data = await coro
  File "e:\Рабочий стол\house_manager_TG\Utility\database_connector.py", line 105, in get_report_with_current_date
    ans = self.cursor.execute(
sqlite3.OperationalError: no such column: id

05.12.2022 16:14:01:141|DEBUG|Api.api bug_catcher line:68|Ошибка /get_report_with_current_date/
Traceback (most recent call last):
  File "e:\Рабочий стол\house_manager_TG\Api\api.py", line 56, in bug_catcher
    data = await coro
  File "e:\Рабочий стол\house_manager_TG\Utility\database_connector.py", line 105, in get_report_with_current_date
    ans = self.cursor.execute(
sqlite3.OperationalError: no such column: id

05.12.2022 16:14:03:143|DEBUG|Api.api bug_catcher line:68|Ошибка /get_report_with_current_date/
Traceback (most recent call last):
  File "e:\Рабочий стол\house_manager_TG\Api\api.py", line 56, in bug_catcher
    data = await coro
  File "e:\Рабочий стол\house_manager_TG\Utility\database_connector.py", line 105, in get_report_with_current_date
    ans = self.cursor.execute(
sqlite3.OperationalError: no such column: id

05.12.2022 16:14:03:143|DEBUG|Api.api bug_catcher line:68|Ошибка /get_report_with_current_date/
Traceback (most recent call last):
  File "e:\Рабочий стол\house_manager_TG\Api\api.py", line 56, in bug_catcher
    data = await coro
  File "e:\Рабочий стол\house_manager_TG\Utility\database_connector.py", line 105, in get_report_with_current_date
    ans = self.cursor.execute(
sqlite3.OperationalError: no such column: id

05.12.2022 16:14:03:143|DEBUG|Api.api bug_catcher line:68|Ошибка /get_report_with_current_date/
Traceback (most recent call last):
  File "e:\Рабочий стол\house_manager_TG\Api\api.py", line 56, in bug_catcher
    data = await coro
  File "e:\Рабочий стол\house_manager_TG\Utility\database_connector.py", line 105, in get_report_with_current_date
    ans = self.cursor.execute(
sqlite3.OperationalError: no such column: id

05.12.2022 16:14:03:143|DEBUG|Api.api bug_catcher line:68|Ошибка /get_report_with_current_date/
Traceback (most recent call last):
  File "e:\Рабочий стол\house_manager_TG\Api\api.py", line 56, in bug_catcher
    data = await coro
  File "e:\Рабочий стол\house_manager_TG\Utility\database_connector.py", line 105, in get_report_with_current_date
    ans = self.cursor.execute(
sqlite3.OperationalError: no such column: id

05.12.2022 16:14:03:143|DEBUG|Api.api bug_catcher line:68|Ошибка /get_report_with_current_date/
Traceback (most recent call last):
  File "e:\Рабочий стол\house_manager_TG\Api\api.py", line 56, in bug_catcher
    data = await coro
  File "e:\Рабочий стол\house_manager_TG\Utility\database_connector.py", line 105, in get_report_with_current_date
    ans = self.cursor.execute(
sqlite3.OperationalError: no such column: id

05.12.2022 16:14:07:147|DEBUG|Api.api bug_catcher line:68|Ошибка /get_report_with_current_date/
Traceback (most recent call last):
  File "e:\Рабочий стол\house_manager_TG\Api\api.py", line 56, in bug_catcher
    data = await coro
  File "e:\Рабочий стол\house_manager_TG\Utility\database_connector.py", line 118, in get_report_with_current_date
    self.cursor.execute(_str)
sqlite3.OperationalError: table Основной_дом_it has 6 columns but 4 values were supplied

05.12.2022 16:14:07:147|DEBUG|Api.api bug_catcher line:68|Ошибка /get_report_with_current_date/
Traceback (most recent call last):
  File "e:\Рабочий стол\house_manager_TG\Api\api.py", line 56, in bug_catcher
    data = await coro
  File "e:\Рабочий стол\house_manager_TG\Utility\database_connector.py", line 118, in get_report_with_current_date
    self.cursor.execute(_str)
sqlite3.OperationalError: table Основной_дом_it has 6 columns but 4 values were supplied

05.12.2022 16:14:07:147|DEBUG|Api.api bug_catcher line:68|Ошибка /get_report_with_current_date/
Traceback (most recent call last):
  File "e:\Рабочий стол\house_manager_TG\Api\api.py", line 56, in bug_catcher
    data = await coro
  File "e:\Рабочий стол\house_manager_TG\Utility\database_connector.py", line 118, in get_report_with_current_date
    self.cursor.execute(_str)
sqlite3.OperationalError: table Основной_дом_it has 6 columns but 4 values were supplied

05.12.2022 16:14:07:147|DEBUG|Api.api bug_catcher line:68|Ошибка /get_report_with_current_date/
Traceback (most recent call last):
  File "e:\Рабочий стол\house_manager_TG\Api\api.py", line 56, in bug_catcher
    data = await coro
  File "e:\Рабочий стол\house_manager_TG\Utility\database_connector.py", line 118, in get_report_with_current_date
    self.cursor.execute(_str)
sqlite3.OperationalError: table Основной_дом_it has 6 columns but 4 values were supplied

05.12.2022 16:14:07:147|DEBUG|Api.api bug_catcher line:68|Ошибка /get_report_with_current_date/
Traceback (most recent call last):
  File "e:\Рабочий стол\house_manager_TG\Api\api.py", line 56, in bug_catcher
    data = await coro
  File "e:\Рабочий стол\house_manager_TG\Utility\database_connector.py", line 118, in get_report_with_current_date
    self.cursor.execute(_str)
sqlite3.OperationalError: table Основной_дом_it has 6 columns but 4 values were supplied

05.12.2022 16:19:48:1948|INFO|TG.handlers on_startup line:20|send main menu
05.12.2022 16:19:53:1953|DEBUG|Api.api bug_catcher line:75|Ошибка /get_report_with_current_date/
Traceback (most recent call last):
  File "e:\Рабочий стол\house_manager_TG\Api\api.py", line 63, in bug_catcher
    data = await coro
  File "e:\Рабочий стол\house_manager_TG\Utility\database_connector.py", line 118, in get_report_with_current_date
    self.cursor.execute(_str)
sqlite3.OperationalError: table Основной_дом_it has 6 columns but 4 values were supplied

05.12.2022 16:19:53:1953|DEBUG|Api.api bug_catcher line:75|Ошибка /get_report_with_current_date/
Traceback (most recent call last):
  File "e:\Рабочий стол\house_manager_TG\Api\api.py", line 63, in bug_catcher
    data = await coro
  File "e:\Рабочий стол\house_manager_TG\Utility\database_connector.py", line 118, in get_report_with_current_date
    self.cursor.execute(_str)
sqlite3.OperationalError: table Основной_дом_it has 6 columns but 4 values were supplied

05.12.2022 16:19:53:1953|DEBUG|Api.api bug_catcher line:75|Ошибка /get_report_with_current_date/
Traceback (most recent call last):
  File "e:\Рабочий стол\house_manager_TG\Api\api.py", line 63, in bug_catcher
    data = await coro
  File "e:\Рабочий стол\house_manager_TG\Utility\database_connector.py", line 118, in get_report_with_current_date
    self.cursor.execute(_str)
sqlite3.OperationalError: table Основной_дом_it has 6 columns but 4 values were supplied

05.12.2022 16:19:53:1953|DEBUG|Api.api bug_catcher line:75|Ошибка /get_report_with_current_date/
Traceback (most recent call last):
  File "e:\Рабочий стол\house_manager_TG\Api\api.py", line 63, in bug_catcher
    data = await coro
  File "e:\Рабочий стол\house_manager_TG\Utility\database_connector.py", line 118, in get_report_with_current_date
    self.cursor.execute(_str)
sqlite3.OperationalError: table Основной_дом_it has 6 columns but 4 values were supplied

05.12.2022 16:19:53:1953|DEBUG|Api.api bug_catcher line:75|Ошибка /get_report_with_current_date/
Traceback (most recent call last):
  File "e:\Рабочий стол\house_manager_TG\Api\api.py", line 63, in bug_catcher
    data = await coro
  File "e:\Рабочий стол\house_manager_TG\Utility\database_connector.py", line 118, in get_report_with_current_date
    self.cursor.execute(_str)
sqlite3.OperationalError: table Основной_дом_it has 6 columns but 4 values were supplied

05.12.2022 16:19:54:1954|DEBUG|Api.api bug_catcher line:75|Ошибка /update_report/
Traceback (most recent call last):
  File "e:\Рабочий стол\house_manager_TG\Api\api.py", line 63, in bug_catcher
    data = await coro
  File "e:\Рабочий стол\house_manager_TG\Utility\database_connector.py", line 144, in update_report
    self.cursor.execute(_str)
sqlite3.OperationalError: no such column: None

05.12.2022 16:19:54:1954|DEBUG|Api.api bug_catcher line:75|Ошибка /update_report/
Traceback (most recent call last):
  File "e:\Рабочий стол\house_manager_TG\Api\api.py", line 63, in bug_catcher
    data = await coro
  File "e:\Рабочий стол\house_manager_TG\Utility\database_connector.py", line 144, in update_report
    self.cursor.execute(_str)
sqlite3.OperationalError: no such column: None

05.12.2022 16:19:54:1954|DEBUG|Api.api bug_catcher line:75|Ошибка /update_report/
Traceback (most recent call last):
  File "e:\Рабочий стол\house_manager_TG\Api\api.py", line 63, in bug_catcher
    data = await coro
  File "e:\Рабочий стол\house_manager_TG\Utility\database_connector.py", line 144, in update_report
    self.cursor.execute(_str)
sqlite3.OperationalError: no such column: None

05.12.2022 16:19:54:1954|DEBUG|Api.api bug_catcher line:75|Ошибка /update_report/
Traceback (most recent call last):
  File "e:\Рабочий стол\house_manager_TG\Api\api.py", line 63, in bug_catcher
    data = await coro
  File "e:\Рабочий стол\house_manager_TG\Utility\database_connector.py", line 144, in update_report
    self.cursor.execute(_str)
sqlite3.OperationalError: no such column: None

05.12.2022 16:19:54:1954|DEBUG|Api.api bug_catcher line:75|Ошибка /update_report/
Traceback (most recent call last):
  File "e:\Рабочий стол\house_manager_TG\Api\api.py", line 63, in bug_catcher
    data = await coro
  File "e:\Рабочий стол\house_manager_TG\Utility\database_connector.py", line 144, in update_report
    self.cursor.execute(_str)
sqlite3.OperationalError: no such column: None

05.12.2022 16:20:58:2058|INFO|TG.handlers on_startup line:20|send main menu
05.12.2022 16:21:01:211|DEBUG|Api.api bug_catcher line:75|Ошибка /get_report_with_current_date/
Traceback (most recent call last):
  File "e:\Рабочий стол\house_manager_TG\Api\api.py", line 63, in bug_catcher
    data = await coro
  File "e:\Рабочий стол\house_manager_TG\Utility\database_connector.py", line 118, in get_report_with_current_date
    self.cursor.execute(_str)
sqlite3.OperationalError: table Основной_дом_it has 6 columns but 4 values were supplied

05.12.2022 16:21:01:211|DEBUG|Api.api bug_catcher line:75|Ошибка /get_report_with_current_date/
Traceback (most recent call last):
  File "e:\Рабочий стол\house_manager_TG\Api\api.py", line 63, in bug_catcher
    data = await coro
  File "e:\Рабочий стол\house_manager_TG\Utility\database_connector.py", line 118, in get_report_with_current_date
    self.cursor.execute(_str)
sqlite3.OperationalError: table Основной_дом_it has 6 columns but 4 values were supplied

05.12.2022 16:21:01:211|DEBUG|Api.api bug_catcher line:75|Ошибка /get_report_with_current_date/
Traceback (most recent call last):
  File "e:\Рабочий стол\house_manager_TG\Api\api.py", line 63, in bug_catcher
    data = await coro
  File "e:\Рабочий стол\house_manager_TG\Utility\database_connector.py", line 118, in get_report_with_current_date
    self.cursor.execute(_str)
sqlite3.OperationalError: table Основной_дом_it has 6 columns but 4 values were supplied

05.12.2022 16:21:01:211|DEBUG|Api.api bug_catcher line:75|Ошибка /get_report_with_current_date/
Traceback (most recent call last):
  File "e:\Рабочий стол\house_manager_TG\Api\api.py", line 63, in bug_catcher
    data = await coro
  File "e:\Рабочий стол\house_manager_TG\Utility\database_connector.py", line 118, in get_report_with_current_date
    self.cursor.execute(_str)
sqlite3.OperationalError: table Основной_дом_it has 6 columns but 4 values were supplied

05.12.2022 16:21:01:211|DEBUG|Api.api bug_catcher line:75|Ошибка /get_report_with_current_date/
Traceback (most recent call last):
  File "e:\Рабочий стол\house_manager_TG\Api\api.py", line 63, in bug_catcher
    data = await coro
  File "e:\Рабочий стол\house_manager_TG\Utility\database_connector.py", line 118, in get_report_with_current_date
    self.cursor.execute(_str)
sqlite3.OperationalError: table Основной_дом_it has 6 columns but 4 values were supplied

05.12.2022 16:21:45:2145|INFO|TG.handlers on_startup line:20|send main menu
05.12.2022 16:21:50:2150|DEBUG|Api.api bug_catcher line:75|Ошибка /get_report_with_current_date/
Traceback (most recent call last):
  File "e:\Рабочий стол\house_manager_TG\Api\api.py", line 63, in bug_catcher
    data = await coro
  File "e:\Рабочий стол\house_manager_TG\Utility\database_connector.py", line 121, in get_report_with_current_date
    for i in len(cols):
TypeError: 'int' object is not iterable

05.12.2022 16:21:50:2150|DEBUG|Api.api bug_catcher line:75|Ошибка /get_report_with_current_date/
Traceback (most recent call last):
  File "e:\Рабочий стол\house_manager_TG\Api\api.py", line 63, in bug_catcher
    data = await coro
  File "e:\Рабочий стол\house_manager_TG\Utility\database_connector.py", line 121, in get_report_with_current_date
    for i in len(cols):
TypeError: 'int' object is not iterable

05.12.2022 16:21:50:2150|DEBUG|Api.api bug_catcher line:75|Ошибка /get_report_with_current_date/
Traceback (most recent call last):
  File "e:\Рабочий стол\house_manager_TG\Api\api.py", line 63, in bug_catcher
    data = await coro
  File "e:\Рабочий стол\house_manager_TG\Utility\database_connector.py", line 121, in get_report_with_current_date
    for i in len(cols):
TypeError: 'int' object is not iterable

05.12.2022 16:21:50:2150|DEBUG|Api.api bug_catcher line:75|Ошибка /get_report_with_current_date/
Traceback (most recent call last):
  File "e:\Рабочий стол\house_manager_TG\Api\api.py", line 63, in bug_catcher
    data = await coro
  File "e:\Рабочий стол\house_manager_TG\Utility\database_connector.py", line 121, in get_report_with_current_date
    for i in len(cols):
TypeError: 'int' object is not iterable

05.12.2022 16:21:50:2150|DEBUG|Api.api bug_catcher line:75|Ошибка /get_report_with_current_date/
Traceback (most recent call last):
  File "e:\Рабочий стол\house_manager_TG\Api\api.py", line 63, in bug_catcher
    data = await coro
  File "e:\Рабочий стол\house_manager_TG\Utility\database_connector.py", line 121, in get_report_with_current_date
    for i in len(cols):
TypeError: 'int' object is not iterable

05.12.2022 16:22:57:2257|INFO|TG.handlers on_startup line:20|send main menu
05.12.2022 16:23:22:2322|INFO|TG.handlers on_startup line:20|send main menu
05.12.2022 16:24:29:2429|INFO|TG.handlers on_startup line:20|send main menu
05.12.2022 16:24:45:2445|INFO|TG.handlers on_startup line:20|send main menu
05.12.2022 16:25:12:2512|INFO|TG.handlers on_startup line:20|send main menu
05.12.2022 16:25:16:2516|DEBUG|Api.api bug_catcher line:75|Ошибка /update_report/
Traceback (most recent call last):
  File "e:\Рабочий стол\house_manager_TG\Api\api.py", line 63, in bug_catcher
    data = await coro
  File "e:\Рабочий стол\house_manager_TG\Utility\database_connector.py", line 144, in update_report
    self.cursor.execute(_str)
sqlite3.OperationalError: no such column: None

05.12.2022 16:25:16:2516|DEBUG|Api.api bug_catcher line:75|Ошибка /update_report/
Traceback (most recent call last):
  File "e:\Рабочий стол\house_manager_TG\Api\api.py", line 63, in bug_catcher
    data = await coro
  File "e:\Рабочий стол\house_manager_TG\Utility\database_connector.py", line 144, in update_report
    self.cursor.execute(_str)
sqlite3.OperationalError: no such column: None

05.12.2022 16:25:16:2516|DEBUG|Api.api bug_catcher line:75|Ошибка /update_report/
Traceback (most recent call last):
  File "e:\Рабочий стол\house_manager_TG\Api\api.py", line 63, in bug_catcher
    data = await coro
  File "e:\Рабочий стол\house_manager_TG\Utility\database_connector.py", line 144, in update_report
    self.cursor.execute(_str)
sqlite3.OperationalError: no such column: None

05.12.2022 16:25:16:2516|DEBUG|Api.api bug_catcher line:75|Ошибка /update_report/
Traceback (most recent call last):
  File "e:\Рабочий стол\house_manager_TG\Api\api.py", line 63, in bug_catcher
    data = await coro
  File "e:\Рабочий стол\house_manager_TG\Utility\database_connector.py", line 144, in update_report
    self.cursor.execute(_str)
sqlite3.OperationalError: no such column: None

05.12.2022 16:25:16:2516|DEBUG|Api.api bug_catcher line:75|Ошибка /update_report/
Traceback (most recent call last):
  File "e:\Рабочий стол\house_manager_TG\Api\api.py", line 63, in bug_catcher
    data = await coro
  File "e:\Рабочий стол\house_manager_TG\Utility\database_connector.py", line 144, in update_report
    self.cursor.execute(_str)
sqlite3.OperationalError: no such column: None

05.12.2022 16:26:11:2611|INFO|TG.handlers on_startup line:20|send main menu
05.12.2022 16:26:18:2618|DEBUG|Api.api bug_catcher line:75|Ошибка /update_report/
Traceback (most recent call last):
  File "e:\Рабочий стол\house_manager_TG\Api\api.py", line 63, in bug_catcher
    data = await coro
  File "e:\Рабочий стол\house_manager_TG\Utility\database_connector.py", line 144, in update_report
    self.cursor.execute(_str)
sqlite3.OperationalError: no such column: None

05.12.2022 16:26:18:2618|DEBUG|Api.api bug_catcher line:75|Ошибка /update_report/
Traceback (most recent call last):
  File "e:\Рабочий стол\house_manager_TG\Api\api.py", line 63, in bug_catcher
    data = await coro
  File "e:\Рабочий стол\house_manager_TG\Utility\database_connector.py", line 144, in update_report
    self.cursor.execute(_str)
sqlite3.OperationalError: no such column: None

05.12.2022 16:26:18:2618|DEBUG|Api.api bug_catcher line:75|Ошибка /update_report/
Traceback (most recent call last):
  File "e:\Рабочий стол\house_manager_TG\Api\api.py", line 63, in bug_catcher
    data = await coro
  File "e:\Рабочий стол\house_manager_TG\Utility\database_connector.py", line 144, in update_report
    self.cursor.execute(_str)
sqlite3.OperationalError: no such column: None

05.12.2022 16:26:18:2618|DEBUG|Api.api bug_catcher line:75|Ошибка /update_report/
Traceback (most recent call last):
  File "e:\Рабочий стол\house_manager_TG\Api\api.py", line 63, in bug_catcher
    data = await coro
  File "e:\Рабочий стол\house_manager_TG\Utility\database_connector.py", line 144, in update_report
    self.cursor.execute(_str)
sqlite3.OperationalError: no such column: None

05.12.2022 16:26:18:2618|DEBUG|Api.api bug_catcher line:75|Ошибка /update_report/
Traceback (most recent call last):
  File "e:\Рабочий стол\house_manager_TG\Api\api.py", line 63, in bug_catcher
    data = await coro
  File "e:\Рабочий стол\house_manager_TG\Utility\database_connector.py", line 144, in update_report
    self.cursor.execute(_str)
sqlite3.OperationalError: no such column: None

05.12.2022 16:27:40:2740|INFO|TG.handlers on_startup line:20|send main menu
05.12.2022 16:27:43:2743|DEBUG|Api.api bug_catcher line:75|Ошибка /update_report/
Traceback (most recent call last):
  File "e:\Рабочий стол\house_manager_TG\Api\api.py", line 63, in bug_catcher
    data = await coro
  File "e:\Рабочий стол\house_manager_TG\Utility\database_connector.py", line 146, in update_report
    self.cursor.execute(_str)
sqlite3.OperationalError: no such column: None

05.12.2022 16:27:43:2743|DEBUG|Api.api bug_catcher line:75|Ошибка /update_report/
Traceback (most recent call last):
  File "e:\Рабочий стол\house_manager_TG\Api\api.py", line 63, in bug_catcher
    data = await coro
  File "e:\Рабочий стол\house_manager_TG\Utility\database_connector.py", line 146, in update_report
    self.cursor.execute(_str)
sqlite3.OperationalError: no such column: None

05.12.2022 16:27:43:2743|DEBUG|Api.api bug_catcher line:75|Ошибка /update_report/
Traceback (most recent call last):
  File "e:\Рабочий стол\house_manager_TG\Api\api.py", line 63, in bug_catcher
    data = await coro
  File "e:\Рабочий стол\house_manager_TG\Utility\database_connector.py", line 146, in update_report
    self.cursor.execute(_str)
sqlite3.OperationalError: no such column: None

05.12.2022 16:27:43:2743|DEBUG|Api.api bug_catcher line:75|Ошибка /update_report/
Traceback (most recent call last):
  File "e:\Рабочий стол\house_manager_TG\Api\api.py", line 63, in bug_catcher
    data = await coro
  File "e:\Рабочий стол\house_manager_TG\Utility\database_connector.py", line 146, in update_report
    self.cursor.execute(_str)
sqlite3.OperationalError: no such column: None

05.12.2022 16:27:43:2743|DEBUG|Api.api bug_catcher line:75|Ошибка /update_report/
Traceback (most recent call last):
  File "e:\Рабочий стол\house_manager_TG\Api\api.py", line 63, in bug_catcher
    data = await coro
  File "e:\Рабочий стол\house_manager_TG\Utility\database_connector.py", line 146, in update_report
    self.cursor.execute(_str)
sqlite3.OperationalError: no such column: None

05.12.2022 16:28:23:2823|INFO|TG.handlers on_startup line:20|send main menu
05.12.2022 16:34:11:3411|INFO|TG.handlers on_startup line:20|send main menu
05.12.2022 16:36:02:362|INFO|TG.handlers on_startup line:20|send main menu
05.12.2022 16:38:31:3831|INFO|TG.handlers on_startup line:20|send main menu
05.12.2022 16:39:02:392|INFO|TG.handlers on_startup line:20|send main menu
05.12.2022 16:50:56:5056|INFO|TG.handlers on_startup line:20|send main menu
05.12.2022 16:51:17:5117|INFO|TG.handlers on_startup line:20|send main menu
05.12.2022 16:53:54:5354|INFO|TG.handlers on_startup line:20|send main menu
05.12.2022 16:54:22:5422|INFO|TG.handlers on_startup line:20|send main menu
05.12.2022 16:55:05:555|INFO|TG.handlers on_startup line:20|send main menu
05.12.2022 16:56:30:5630|DEBUG|Api.api bug_catcher line:75|Ошибка /get_report_with_current_date/
Traceback (most recent call last):
  File "e:\Рабочий стол\house_manager_TG\Api\api.py", line 63, in bug_catcher
    data = await coro
  File "e:\Рабочий стол\house_manager_TG\Utility\database_connector.py", line 105, in get_report_with_current_date
    ans = self.cursor.execute(
sqlite3.OperationalError: no such column: id

05.12.2022 16:56:30:5630|DEBUG|Api.api bug_catcher line:75|Ошибка /get_report_with_current_date/
Traceback (most recent call last):
  File "e:\Рабочий стол\house_manager_TG\Api\api.py", line 63, in bug_catcher
    data = await coro
  File "e:\Рабочий стол\house_manager_TG\Utility\database_connector.py", line 105, in get_report_with_current_date
    ans = self.cursor.execute(
sqlite3.OperationalError: no such column: id

05.12.2022 16:56:30:5630|DEBUG|Api.api bug_catcher line:75|Ошибка /get_report_with_current_date/
Traceback (most recent call last):
  File "e:\Рабочий стол\house_manager_TG\Api\api.py", line 63, in bug_catcher
    data = await coro
  File "e:\Рабочий стол\house_manager_TG\Utility\database_connector.py", line 105, in get_report_with_current_date
    ans = self.cursor.execute(
sqlite3.OperationalError: no such column: id

05.12.2022 16:56:30:5630|DEBUG|Api.api bug_catcher line:75|Ошибка /get_report_with_current_date/
Traceback (most recent call last):
  File "e:\Рабочий стол\house_manager_TG\Api\api.py", line 63, in bug_catcher
    data = await coro
  File "e:\Рабочий стол\house_manager_TG\Utility\database_connector.py", line 105, in get_report_with_current_date
    ans = self.cursor.execute(
sqlite3.OperationalError: no such column: id

05.12.2022 16:56:30:5630|DEBUG|Api.api bug_catcher line:75|Ошибка /get_report_with_current_date/
Traceback (most recent call last):
  File "e:\Рабочий стол\house_manager_TG\Api\api.py", line 63, in bug_catcher
    data = await coro
  File "e:\Рабочий стол\house_manager_TG\Utility\database_connector.py", line 105, in get_report_with_current_date
    ans = self.cursor.execute(
sqlite3.OperationalError: no such column: id

05.12.2022 16:57:21:5721|INFO|TG.handlers on_startup line:20|send main menu
05.12.2022 16:59:17:5917|INFO|TG.handlers on_startup line:20|send main menu
05.12.2022 17:00:39:039|INFO|TG.handlers on_startup line:20|send main menu
05.12.2022 17:24:49:2449|INFO|TG.handlers on_startup line:20|send main menu
05.12.2022 17:26:21:2621|INFO|TG.handlers on_startup line:20|send main menu
05.12.2022 17:27:53:2753|INFO|TG.handlers on_startup line:20|send main menu
05.12.2022 17:29:11:2911|INFO|TG.handlers on_startup line:20|send main menu
05.12.2022 17:30:27:3027|INFO|TG.handlers on_startup line:20|send main menu
05.12.2022 17:31:43:3143|INFO|TG.handlers on_startup line:20|send main menu
05.12.2022 17:32:37:3237|INFO|TG.handlers on_startup line:20|send main menu
05.12.2022 17:33:28:3328|INFO|TG.handlers on_startup line:20|send main menu
05.12.2022 17:39:50:3950|INFO|TG.handlers on_startup line:20|send main menu
05.12.2022 17:47:17:4717|INFO|TG.handlers on_startup line:20|send main menu
05.12.2022 19:28:11:2811|INFO|TG.handlers on_startup line:20|send main menu
05.12.2022 19:29:01:291|INFO|TG.handlers on_startup line:20|send main menu
05.12.2022 19:29:52:2952|INFO|TG.handlers on_startup line:20|send main menu
05.12.2022 19:30:06:306|INFO|TG.handlers on_startup line:20|send main menu
05.12.2022 19:31:17:3117|INFO|TG.handlers on_startup line:20|send main menu
05.12.2022 19:32:54:3254|INFO|TG.handlers on_startup line:20|send main menu
05.12.2022 19:33:25:3325|INFO|TG.handlers on_startup line:20|send main menu
05.12.2022 19:34:34:3434|INFO|TG.handlers on_startup line:20|send main menu
05.12.2022 19:35:03:353|INFO|TG.handlers on_startup line:20|send main menu
05.12.2022 19:37:03:373|INFO|TG.handlers on_startup line:20|send main menu
05.12.2022 19:43:03:433|INFO|TG.handlers on_startup line:21|send main menu
05.12.2022 19:44:00:440|INFO|TG.handlers on_startup line:21|send main menu
05.12.2022 19:46:00:460|INFO|TG.handlers on_startup line:21|send main menu
05.12.2022 19:46:35:4635|INFO|TG.handlers on_startup line:21|send main menu
05.12.2022 19:48:08:488|INFO|TG.handlers on_startup line:21|send main menu
05.12.2022 19:50:28:5028|INFO|TG.handlers on_startup line:21|send main menu
05.12.2022 19:51:19:5119|INFO|TG.handlers on_startup line:21|send main menu
05.12.2022 19:53:30:5330|INFO|TG.handlers on_startup line:21|send main menu
05.12.2022 19:54:20:5420|INFO|TG.handlers on_startup line:21|send main menu
05.12.2022 19:55:25:5525|INFO|TG.handlers on_startup line:21|send main menu
05.12.2022 19:58:02:582|INFO|TG.handlers on_startup line:21|send main menu
05.12.2022 19:58:18:5818|INFO|TG.handlers on_startup line:21|send main menu
05.12.2022 19:59:52:5952|INFO|TG.handlers on_startup line:21|send main menu
05.12.2022 20:00:37:037|INFO|TG.handlers on_startup line:21|send main menu
05.12.2022 20:10:03:103|INFO|TG.handlers on_startup line:21|send main menu
05.12.2022 20:12:19:1219|INFO|TG.handlers on_startup line:21|send main menu
05.12.2022 20:13:10:1310|INFO|TG.handlers on_startup line:21|send main menu
05.12.2022 20:15:32:1532|INFO|TG.handlers on_startup line:21|send main menu
05.12.2022 20:18:07:187|INFO|TG.handlers on_startup line:21|send main menu
05.12.2022 20:20:37:2037|INFO|TG.handlers on_startup line:21|send main menu
05.12.2022 20:20:41:2041|DEBUG|Api.api bug_catcher line:75|Ошибка /update_user/
Traceback (most recent call last):
  File "e:\Рабочий стол\house_manager_TG\Api\api.py", line 63, in bug_catcher
    data = await coro
  File "e:\Рабочий стол\house_manager_TG\Utility\database_connector.py", line 79, in update_user
    self.cursor.execute(_str)
sqlite3.OperationalError: no such column: None

05.12.2022 20:20:41:2041|DEBUG|Api.api bug_catcher line:75|Ошибка /update_user/
Traceback (most recent call last):
  File "e:\Рабочий стол\house_manager_TG\Api\api.py", line 63, in bug_catcher
    data = await coro
  File "e:\Рабочий стол\house_manager_TG\Utility\database_connector.py", line 79, in update_user
    self.cursor.execute(_str)
sqlite3.OperationalError: no such column: None

05.12.2022 20:20:41:2041|DEBUG|Api.api bug_catcher line:75|Ошибка /update_user/
Traceback (most recent call last):
  File "e:\Рабочий стол\house_manager_TG\Api\api.py", line 63, in bug_catcher
    data = await coro
  File "e:\Рабочий стол\house_manager_TG\Utility\database_connector.py", line 79, in update_user
    self.cursor.execute(_str)
sqlite3.OperationalError: no such column: None

05.12.2022 20:20:41:2041|DEBUG|Api.api bug_catcher line:75|Ошибка /update_user/
Traceback (most recent call last):
  File "e:\Рабочий стол\house_manager_TG\Api\api.py", line 63, in bug_catcher
    data = await coro
  File "e:\Рабочий стол\house_manager_TG\Utility\database_connector.py", line 79, in update_user
    self.cursor.execute(_str)
sqlite3.OperationalError: no such column: None

05.12.2022 20:20:41:2041|DEBUG|Api.api bug_catcher line:75|Ошибка /update_user/
Traceback (most recent call last):
  File "e:\Рабочий стол\house_manager_TG\Api\api.py", line 63, in bug_catcher
    data = await coro
  File "e:\Рабочий стол\house_manager_TG\Utility\database_connector.py", line 79, in update_user
    self.cursor.execute(_str)
sqlite3.OperationalError: no such column: None

05.12.2022 20:21:57:2157|DEBUG|Api.api bug_catcher line:75|Ошибка /update_user/
Traceback (most recent call last):
  File "e:\Рабочий стол\house_manager_TG\Api\api.py", line 63, in bug_catcher
    data = await coro
  File "e:\Рабочий стол\house_manager_TG\Utility\database_connector.py", line 79, in update_user
    self.cursor.execute(_str)
sqlite3.OperationalError: no such column: None

05.12.2022 20:21:57:2157|DEBUG|Api.api bug_catcher line:75|Ошибка /update_user/
Traceback (most recent call last):
  File "e:\Рабочий стол\house_manager_TG\Api\api.py", line 63, in bug_catcher
    data = await coro
  File "e:\Рабочий стол\house_manager_TG\Utility\database_connector.py", line 79, in update_user
    self.cursor.execute(_str)
sqlite3.OperationalError: no such column: None

05.12.2022 20:21:57:2157|DEBUG|Api.api bug_catcher line:75|Ошибка /update_user/
Traceback (most recent call last):
  File "e:\Рабочий стол\house_manager_TG\Api\api.py", line 63, in bug_catcher
    data = await coro
  File "e:\Рабочий стол\house_manager_TG\Utility\database_connector.py", line 79, in update_user
    self.cursor.execute(_str)
sqlite3.OperationalError: no such column: None

05.12.2022 20:21:57:2157|DEBUG|Api.api bug_catcher line:75|Ошибка /update_user/
Traceback (most recent call last):
  File "e:\Рабочий стол\house_manager_TG\Api\api.py", line 63, in bug_catcher
    data = await coro
  File "e:\Рабочий стол\house_manager_TG\Utility\database_connector.py", line 79, in update_user
    self.cursor.execute(_str)
sqlite3.OperationalError: no such column: None

05.12.2022 20:21:57:2157|DEBUG|Api.api bug_catcher line:75|Ошибка /update_user/
Traceback (most recent call last):
  File "e:\Рабочий стол\house_manager_TG\Api\api.py", line 63, in bug_catcher
    data = await coro
  File "e:\Рабочий стол\house_manager_TG\Utility\database_connector.py", line 79, in update_user
    self.cursor.execute(_str)
sqlite3.OperationalError: no such column: None

05.12.2022 20:22:19:2219|INFO|TG.handlers on_startup line:21|send main menu
05.12.2022 20:22:23:2223|DEBUG|Api.api bug_catcher line:75|Ошибка /update_user/
Traceback (most recent call last):
  File "e:\Рабочий стол\house_manager_TG\Api\api.py", line 63, in bug_catcher
    data = await coro
  File "e:\Рабочий стол\house_manager_TG\Utility\database_connector.py", line 80, in update_user
    self.cursor.execute(_str)
sqlite3.OperationalError: no such column: None

05.12.2022 20:22:23:2223|DEBUG|Api.api bug_catcher line:75|Ошибка /update_user/
Traceback (most recent call last):
  File "e:\Рабочий стол\house_manager_TG\Api\api.py", line 63, in bug_catcher
    data = await coro
  File "e:\Рабочий стол\house_manager_TG\Utility\database_connector.py", line 80, in update_user
    self.cursor.execute(_str)
sqlite3.OperationalError: no such column: None

05.12.2022 20:22:23:2223|DEBUG|Api.api bug_catcher line:75|Ошибка /update_user/
Traceback (most recent call last):
  File "e:\Рабочий стол\house_manager_TG\Api\api.py", line 63, in bug_catcher
    data = await coro
  File "e:\Рабочий стол\house_manager_TG\Utility\database_connector.py", line 80, in update_user
    self.cursor.execute(_str)
sqlite3.OperationalError: no such column: None

05.12.2022 20:22:23:2223|DEBUG|Api.api bug_catcher line:75|Ошибка /update_user/
Traceback (most recent call last):
  File "e:\Рабочий стол\house_manager_TG\Api\api.py", line 63, in bug_catcher
    data = await coro
  File "e:\Рабочий стол\house_manager_TG\Utility\database_connector.py", line 80, in update_user
    self.cursor.execute(_str)
sqlite3.OperationalError: no such column: None

05.12.2022 20:22:23:2223|DEBUG|Api.api bug_catcher line:75|Ошибка /update_user/
Traceback (most recent call last):
  File "e:\Рабочий стол\house_manager_TG\Api\api.py", line 63, in bug_catcher
    data = await coro
  File "e:\Рабочий стол\house_manager_TG\Utility\database_connector.py", line 80, in update_user
    self.cursor.execute(_str)
sqlite3.OperationalError: no such column: None

05.12.2022 20:40:22:4022|INFO|TG.handlers on_startup line:22|send main menu
05.12.2022 20:41:33:4133|INFO|TG.handlers on_startup line:22|send main menu
05.12.2022 20:43:31:4331|INFO|TG.handlers on_startup line:22|send main menu
05.12.2022 20:44:42:4442|INFO|TG.handlers on_startup line:22|send main menu
05.12.2022 20:47:07:477|INFO|TG.handlers on_startup line:22|send main menu
05.12.2022 21:04:59:459|INFO|TG.handlers on_startup line:22|send main menu
05.12.2022 21:08:21:821|INFO|TG.handlers on_startup line:22|send main menu
05.12.2022 21:10:32:1032|INFO|TG.handlers on_startup line:22|send main menu
05.12.2022 21:11:45:1145|INFO|TG.handlers on_startup line:22|send main menu
05.12.2022 21:14:44:1444|INFO|TG.handlers on_startup line:22|send main menu
05.12.2022 21:15:24:1524|INFO|TG.handlers on_startup line:22|send main menu
05.12.2022 21:16:18:1618|INFO|TG.handlers on_startup line:22|send main menu
05.12.2022 21:17:05:175|INFO|TG.handlers on_startup line:22|send main menu
05.12.2022 21:17:21:1721|INFO|TG.handlers on_startup line:22|send main menu
05.12.2022 21:18:13:1813|INFO|TG.handlers on_startup line:22|send main menu
06.12.2022 08:36:45:3645|INFO|TG.handlers on_startup line:22|send main menu
06.12.2022 08:49:31:4931|INFO|TG.handlers on_startup line:22|send main menu
06.12.2022 09:30:32:3032|INFO|TG.handlers on_startup line:22|send main menu
06.12.2022 09:44:40:4440|INFO|TG.handlers on_startup line:22|send main menu
06.12.2022 09:45:06:456|INFO|TG.handlers on_startup line:22|send main menu
06.12.2022 10:00:56:056|INFO|TG.handlers on_startup line:22|send main menu
06.12.2022 18:23:19:2319|INFO|TG.handlers on_startup line:22|send main menu
06.12.2022 18:27:22:2722|INFO|TG.handlers on_startup line:22|send main menu
06.12.2022 18:28:25:2825|INFO|TG.handlers on_startup line:22|send main menu
06.12.2022 23:18:46:1846|INFO|TG.handlers on_startup line:22|send main menu
